<?xml version="1.0" encoding="utf-8"?>
<!-- =================================================================================== -->
<!-- |    This document was autogenerated by xacro from my_robot_integration.urdf.xacro | -->
<!-- |    EDITING THIS FILE BY HAND IS NOT RECOMMENDED                                 | -->
<!-- =================================================================================== -->
<!-- Name your robot here -->
<robot name="my_trolley">
  <link name="dummy_link">
  </link>
  <joint name="dummy_joint" type="fixed">
    <parent link="dummy_link"/>
    <child link="chassis"/>
  </joint>
  <link name="chassis">
    <inertial>
      <origin rpy="0 0 0" xyz="-0.00067553 0.063524 0.00062688"/>
      <mass value="54.648"/>
      <inertia ixx="1.0016" ixy="0.00033127" ixz="0.0022985" iyy="5.1176" iyz="8.1406E-07" izz="4.2622"/>
    </inertial>
    <visual>
      <origin rpy="0 0 0" xyz="0 0 0"/>
      <geometry>
        <mesh filename="package://trolley/meshes/chassis.STL"/>
      </geometry>
      <material name="">
        <color rgba="0.792156862745098 0.819607843137255 0.933333333333333 1"/>
      </material>
    </visual>
    <collision>
      <origin rpy="0 0 0" xyz="0 0 0"/>
      <geometry>
        <mesh filename="package://trolley/meshes/chassis.STL"/>
      </geometry>
    </collision>
  </link>
  <link name="FR_axel">
    <inertial>
      <origin rpy="0 0 0" xyz="-0.04801 -0.012806 -4.996E-16"/>
      <mass value="0.1024"/>
      <inertia ixx="9.193E-05" ixy="-5.2127E-05" ixz="-1.0462E-18" iyy="0.00010816" iyz="-5.5558E-19" izz="0.00019184"/>
    </inertial>
    <visual>
      <origin rpy="0 0 0" xyz="0 0 0"/>
      <geometry>
        <mesh filename="package://trolley/meshes/FR_axel.STL"/>
      </geometry>
      <material name="">
        <color rgba="1 1 0.50196 1"/>
      </material>
    </visual>
    <collision>
      <origin rpy="0 0 0" xyz="0 0 0"/>
      <geometry>
        <mesh filename="package://trolley/meshes/FR_axel.STL"/>
      </geometry>
    </collision>
  </link>
  <joint name="FR_axel_joint" type="revolute">
    <origin rpy="-1.5708 0 -1.5708" xyz="-0.254 0.2032 0"/>
    <parent link="chassis"/>
    <child link="FR_axel"/>
    <axis xyz="0 1 0"/>
    <limit effort="100" lower="-0.550" upper="0.550" velocity="0.1"/>
  </joint>
  <transmission name="FR_steering">
    <type>transmission_interface/SimpleTransmission</type>
    <joint name="FR_axel_joint">
      <hardwareInterface>hardware_interface/EffortJointInterface</hardwareInterface>
    </joint>
    <actuator name="FR_steer">
      <mechanicalReduction>1</mechanicalReduction>
    </actuator>
  </transmission>
  <link name="FR_wheel">
    <inertial>
      <origin rpy="1.57 1.57 1.57" xyz="0.041114161730953 0 1.61772152340589E-07"/>
      <mass value="1.03504952489894"/>
      <inertia ixx="0.00750263692233705" ixy="2.82859959754751E-19" ixz="-3.25422808154387E-09" iyy="0.00424007667712071" iyz="-1.26765657140169E-09" izz="0.00424007754685581"/>
    </inertial>
    <visual>
      <origin rpy="0 0 0" xyz="0 0 0"/>
      <geometry>
        <mesh filename="package://trolley/meshes/FR_wheel.STL"/>
      </geometry>
      <material name="">
        <color rgba="0 0 0 1"/>
      </material>
    </visual>
    <collision>
      <origin rpy="0 0 0" xyz="0 0 0"/>
      <geometry>
        <mesh filename="package://trolley/meshes/FR_wheel.STL"/>
      </geometry>
    </collision>
  </link>
  <joint name="FR_wheel_joint" type="continuous">
    <origin rpy="0 0 3.1416" xyz="-0.08636 -0.0635 0"/>
    <parent link="FR_axel"/>
    <child link="FR_wheel"/>
    <axis xyz="1 0 0"/>
  </joint>
  <link name="FL_axel">
    <inertial>
      <origin rpy="0 0 0" xyz="-0.0480098986905945 0.0128057332127979 1.11022302462516E-16"/>
      <mass value="0.102399166634703"/>
      <inertia ixx="9.19303034326612E-05" ixy="5.21271871393424E-05" ixz="3.51940855755766E-19" iyy="0.000108163475794915" iyz="-2.09225997439903E-19" izz="0.00019183579843432"/>
    </inertial>
    <visual>
      <origin rpy="0 0 0" xyz="0 0 0"/>
      <geometry>
        <mesh filename="package://trolley/meshes/FL_axel.STL"/>
      </geometry>
      <material name="">
        <color rgba="1 1 0.501960784313725 1"/>
      </material>
    </visual>
    <collision>
      <origin rpy="0 0 0" xyz="0 0 0"/>
      <geometry>
        <mesh filename="package://trolley/meshes/FL_axel.STL"/>
      </geometry>
    </collision>
  </link>
  <joint name="FL_axel_joint" type="revolute">
    <origin rpy="1.5708 0 1.5708" xyz="-0.254 -0.2032 0"/>
    <parent link="chassis"/>
    <child link="FL_axel"/>
    <axis xyz="0 1 0"/>
    <limit effort="100" lower="-0.550" upper="0.550" velocity="0.1"/>
  </joint>
  <transmission name="FL_steering">
    <type>transmission_interface/SimpleTransmission</type>
    <joint name="FL_axel_joint">
      <hardwareInterface>hardware_interface/EffortJointInterface</hardwareInterface>
    </joint>
    <actuator name="FL_steer">
      <mechanicalReduction>1</mechanicalReduction>
    </actuator>
  </transmission>
  <link name="FL_wheel">
    <inertial>
      <origin rpy="1.57 1.57 1.57" xyz="0.0411141617309531 -2.4980018054066E-15 1.61772150536477E-07"/>
      <mass value="1.03504952489894"/>
      <inertia ixx="0.00750263692233705" ixy="-3.3461537209577E-17" ixz="-3.25422807026257E-09" iyy="0.00424007667712071" iyz="-1.26765657129531E-09" izz="0.00424007754685581"/>
    </inertial>
    <visual>
      <origin rpy="0 0 0" xyz="0 0 0"/>
      <geometry>
        <mesh filename="package://trolley/meshes/FL_wheel.STL"/>
      </geometry>
      <material name="">
        <color rgba="0 0 0 1"/>
      </material>
    </visual>
    <collision>
      <origin rpy="0 0 0" xyz="0 0 0"/>
      <geometry>
        <mesh filename="package://trolley/meshes/FL_wheel.STL"/>
      </geometry>
    </collision>
  </link>
  <joint name="FL_wheel_joint" type="continuous">
    <origin rpy="-1.5708 0 3.1416" xyz="-0.08636 0.0635 0"/>
    <parent link="FL_axel"/>
    <child link="FL_wheel"/>
    <axis xyz="1 0 0"/>
  </joint>
  <link name="RR_wheel">
    <inertial>
      <origin rpy="0 0 0" xyz="0.194515382739014 7.65254867869658E-07 -7.77335561197301E-07"/>
      <mass value="1.123969088356"/>
      <inertia ixx="0.0075097765327945" ixy="-7.9418378327124E-09" ixz="8.06720962391323E-09" iyy="0.00557336262080405" iyz="-3.48288439538588E-10" izz="0.00557331823532981"/>
    </inertial>
    <visual>
      <origin rpy="0 0 0" xyz="0 0 0"/>
      <geometry>
        <mesh filename="package://trolley/meshes/RR_wheel.STL"/>
      </geometry>
      <material name="">
        <color rgba="0 0 0 1"/>
      </material>
    </visual>
    <collision>
      <origin rpy="0 0 0" xyz="0 0 0"/>
      <geometry>
        <mesh filename="package://trolley/meshes/RR_wheel.STL"/>
      </geometry>
    </collision>
  </link>
  <joint name="RR_wheel_joint" type="continuous">
    <origin rpy="-1.9596 0 1.5708" xyz="0.254 0.127 0.0635"/>
    <parent link="chassis"/>
    <child link="RR_wheel"/>
    <axis xyz="1 0 0"/>
  </joint>
  <transmission name="RR_trans">
    <type>transmission_interface/SimpleTransmission</type>
    <joint name="RR_wheel_joint">
      <hardwareInterface>hardware_interface/VelocityJointInterface</hardwareInterface>
    </joint>
    <actuator name="RR_motor">
      <mechanicalReduction>1</mechanicalReduction>
    </actuator>
  </transmission>
  <link name="RL_wheel">
    <inertial>
      <origin rpy="0 0 0" xyz="0.194515382739014 7.84927678409986E-14 1.09080960153385E-06"/>
      <mass value="1.123969088356"/>
      <inertia ixx="0.0075097765327945" ixy="5.92935843845655E-16" ixz="-1.13204531372023E-08" iyy="0.00557334042739856" iyz="-2.21954699300853E-08" izz="0.0055733404287353"/>
    </inertial>
    <visual>
      <origin rpy="0 0 0" xyz="0 0 0"/>
      <geometry>
        <mesh filename="package://trolley/meshes/RL_wheel.STL"/>
      </geometry>
      <material name="">
        <color rgba="0 0 0 1"/>
      </material>
    </visual>
    <collision>
      <origin rpy="0 0 0" xyz="0 0 0"/>
      <geometry>
        <mesh filename="package://trolley/meshes/RL_wheel.STL"/>
      </geometry>
    </collision>
  </link>
  <joint name="RL_wheel_joint" type="continuous">
    <origin rpy="-1.7639 0 -1.5708" xyz="0.254 -0.127 0.0635"/>
    <parent link="chassis"/>
    <child link="RL_wheel"/>
    <axis xyz="1 0 0"/>
  </joint>
  <transmission name="RL_trans">
    <type>transmission_interface/SimpleTransmission</type>
    <joint name="RL_wheel_joint">
      <hardwareInterface>hardware_interface/VelocityJointInterface</hardwareInterface>
    </joint>
    <actuator name="RL_motor">
      <mechanicalReduction>1</mechanicalReduction>
    </actuator>
  </transmission>
  <link name="base_laser">
    <inertial>
      <origin rpy="0 0 0" xyz="-0.00029774 0.0066667 0.00013047"/>
      <mass value="0.15717"/>
      <inertia ixx="6.7885E-05" ixy="-1.3987E-07" ixz="-8.1554E-07" iyy="0.00013173" iyz="-9.0932E-08" izz="7.1972E-05"/>
    </inertial>
    <visual>
      <origin rpy="0 0 0" xyz="0 0 0"/>
      <geometry>
        <mesh filename="package://trolley/meshes/ydlidar.dae"/>
      </geometry>
      <material name="">
        <color rgba="0.64706 0.61961 0.58824 1"/>
      </material>
    </visual>
    <collision>
      <origin rpy="0 0 0" xyz="0 0 0"/>
      <geometry>
        <mesh filename="package://trolley/meshes/ydlidar.dae"/>
      </geometry>
    </collision>
  </link>
  <link name="laser_frame">
    <inertial>
      <origin rpy="0 0 0" xyz="-0.00036659 0.00064155 -0.00027052"/>
      <mass value="0.25482"/>
      <inertia ixx="8.9194E-05" ixy="1.8116E-07" ixz="3.6435E-08" iyy="0.00018279" iyz="2.423E-07" izz="0.00011103"/>
    </inertial>
    <!--visual>
      <origin
        xyz="0 0 0"
        rpy="0 0 0" />
      <geometry>
        <mesh
          filename="package://trolley/meshes/ydlidar.dae" />
      </geometry>
      <material
        name="">
        <color
          rgba="0.64706 0.61961 0.58824 1" />
      </material>
    </visual-->
    <!--collision>
      <origin
        xyz="0 0 0"
        rpy="0 0 0" />
      <geometry>
        <mesh
          filename="package://trolley/meshes/ydlidar.dae" />
      </geometry>
    </collision-->
  </link>
  <joint name="laser_joint" type="fixed">
    <origin rpy="0 0 0" xyz="0 0 0.03172"/>
    <parent link="base_laser"/>
    <child link="laser_frame"/>
    <axis xyz="0 0 0"/>
  </joint>
  <!-- Add your gazebo sensors here -->
  <gazebo reference="base_laser">
    <sensor name="laser" type="ray">
      <!-- Add in your sensor characteristics -->
      <pose> 0 0 0 0 0 0 </pose>
      <visualise>true</visualise>
      <update_rate>40</update_rate>
      <!-- <always_on>true</always_on> -->
      <ray>
        <scan>
          <horizontal>
            <samples>720</samples>
            <resolution>1</resolution>
            <min_angle>-1.570796</min_angle>
            <max_angle>1.570796</max_angle>
          </horizontal>
        </scan>
        <range>
          <min>0.10</min>
          <max>30.0</max>
          <resolution>0.01</resolution>
        </range>
        <noise>
          <type>gaussian</type>
          <mean>0.0</mean>
          <stddev>0.01</stddev>
        </noise>
      </ray>
      <plugin filename="libgazebo_ros_laser.so" name="gazebo_ros_head_hokuyo_controller">
        <!-- Use topic name as /my_robot/scan -->
        <topicName>/trolley/scan</topicName>
        <frameName>laser_frame</frameName>
      </plugin>
    </sensor>
  </gazebo>
  <!--  Gazebo plugin for control here is already added for you -->
  <gazebo>
    <plugin filename="libgazebo_ros_control.so" name="gazebo_ros_control">
      <robotNamespace>/trolley</robotNamespace>
      <robotSimType>gazebo_ros_control/DefaultRobotHWSim</robotSimType>
      <legacyModeNS>true</legacyModeNS>
    </plugin>
  </gazebo>
  <!-- Create a joint between your robot and sensor -->
  <joint name="laser_chassis_joint" type="fixed">
    <origin rpy="0 0 3.14" xyz="-0.4318 0.0 0.1280"/>
    <parent link="chassis"/>
    <child link="base_laser"/>
  </joint>
  <!-- <joint name="LiDar_joint" type="fixed">
		<origin rpy="0 0 0" xyz="0 0 0"/>
		<parent link="base_laser"/>
		<child link="laser_frame"/>
		<axis xyz="0 0 0"/>
  	</joint> -->
  <gazebo reference="chassis">
    <material>Gazebo/Red</material>
  </gazebo>
  <gazebo reference="FR_axel">
    <material>Gazebo/DarkGrey</material>
  </gazebo>
  <gazebo reference="FL_axel">
    <material>Gazebo/DarkGrey</material>
  </gazebo>
  <gazebo reference="RR_wheel">
    <material>Gazebo/DarkGrey</material>
  </gazebo>
  <gazebo reference="RL_wheel">
    <material>Gazebo/DarkGrey</material>
  </gazebo>
  <gazebo reference="FR_wheel">
    <material>Gazebo/DarkGrey</material>
  </gazebo>
  <gazebo reference="FL_wheel">
    <material>Gazebo/DarkGrey</material>
  </gazebo>
</robot>
